// worker.js - Diferentes tipos de errores para demostraci√≥n

console.log('üîß Worker de demostraci√≥n de errores iniciado');

// Escuchar mensajes del hilo principal
self.onmessage = function(e) {
    const { action, errorType } = e.data;
    
    if (action === 'triggerError') {
        console.log(`‚ö†Ô∏è Worker: Provocando error tipo "${errorType}"`);
        
        switch (errorType) {
            case 'reference':
                // Error de referencia: usar una funci√≥n que no existe
                funcionQueNoExiste(); // Esto lanzar√° un ReferenceError
                break;
                
            case 'type':
                // Error de tipo: intentar llamar algo que no es una funci√≥n
                const notAFunction = "Soy un string";
                notAFunction(); // Esto lanzar√° un TypeError
                break;
                
            case 'math':
                // Error matem√°tico / de rango
                const arr = new Array(-1); // Esto lanzar√° un RangeError
                break;
                
            case 'custom':
                // Lanzar un error personalizado
                throw new Error('Este es un error personalizado lanzado intencionalmente desde el worker');
                
            case 'success':
                // Operaci√≥n exitosa (sin error)
                console.log('‚úÖ Ejecutando operaci√≥n sin errores...');
                
                // Realizar alguna operaci√≥n exitosa
                const result = performSafeOperation();
                
                self.postMessage({
                    message: 'Operaci√≥n completada exitosamente',
                    result: result
                });
                break;
                
            default:
                self.postMessage({
                    message: `Tipo de error desconocido: ${errorType}`
                });
        }
    }
};

// Funci√≥n que se ejecuta sin errores
function performSafeOperation() {
    const numbers = [1, 2, 3, 4, 5];
    const sum = numbers.reduce((acc, num) => acc + num, 0);
    return `Suma de ${numbers.join(' + ')} = ${sum}`;
}

// Tambi√©n podemos manejar errores dentro del worker usando try-catch
function safeOperation() {
    try {
        // C√≥digo que podr√≠a fallar
        riskyOperation();
    } catch (error) {
        // Manejar el error dentro del worker
        console.error('Error manejado dentro del worker:', error);
        
        // Enviar informaci√≥n del error al hilo principal
        self.postMessage({
            error: true,
            message: error.message
        });
    }
}

// Nota importante:
// 
// DIFERENCIA ENTRE ERROR MANEJADO Y NO MANEJADO:
// 
// 1. Error NO manejado (sin try-catch):
//    - Dispara el evento 'onerror' en el hilo principal
//    - Puede detener la ejecuci√≥n del worker
//    - Proporciona informaci√≥n de l√≠nea y columna
// 
// 2. Error MANEJADO (con try-catch):
//    - NO dispara 'onerror' en el hilo principal
//    - Puedes enviar informaci√≥n personalizada con postMessage
//    - Mayor control sobre el manejo del error
//    - El worker contin√∫a funcionando
// 
// MEJORES PR√ÅCTICAS:
// - Siempre define 'onerror' en el hilo principal
// - Usa try-catch para errores esperados
// - Deja que 'onerror' capture errores inesperados
// - Proporciona mensajes de error descriptivos

